Workbook

Sheet SETTORI
P1: =DATE(2025,1,2) -> 45659 | Q1: formula alternat. | S1: =IFERROR(__xludf.DUMMYFUNCTION("(GOOGLEFINANCE(A20,""price"")-INDEX(GOOGLEFINANCE(A20,""price"",""01-01-""&YEAR(TODAY())),2,2))/INDEX(GOOGLEFINANCE(A20,""price"",""01-01-""&YEAR(TODAY())),2,2)"),0.005474705474705419) -> 0.0054747055
I2: Relative Alpha ratio
I3: Rar Day | J3: Rar week | K3: Rar month | L3: Rar quarter | M3: Rar SixM | N3: Rar Year | O3: Ra/momentum | P3: Coerenza trend | Q3: Classifica | R3: Δ-RS (5d) | S3: Situazione | T3: Operatività | U3: Trend 20gg
H4: XLK | I4: =D20-$D$31 -> 0.1 | J4: =(E20-$E$31) -> 0.0057195998 | K4: =(F20-$F$31) -> -0.0082628246 | L4: =(G20-$G$31) -> -0.035321105 | M4: =(H20-$H$31) -> 0.016738042 | N4: =(J20-$J$31) -> 0.078962231 | O4: =(N4*0.15)+(M4*0.25)+(L4*0.3)+(K4*0.2)+(J4*0.1) -> 0.0043519087 | P4: =COUNTIF(I4:M4, ">0") -> 3 | Q4: =RANK(O4, $O$4:$O$14) -> 6 | R4: =IFERROR(HLOOKUP("RS-Mom " & H4, Motore!$AA$1:$AK$2, 2, FALSE), "Dato non trovato") -> 0.02625132 | S4: =IF(O4>0, IF(P4>=4, "LEADER", "IN RECUPERO"), "DEBOLE") -> IN RECUPERO | T4: =IF(AND(R4>0.02, S4="IN RECUPERO"), "🔭 ALERT BUY", IF(AND(Q4<=3, P4>=4, R4>0), "🔥 ACCUMULA", IF(AND(Q4<=3, P4>=4, R4<=0), "📈 MANTIENI", IF(AND(Q4>3, P4>=4), "👀 OSSERVA", "❌ EVITA")))) -> 🔭 ALERT BUY | U4: =IFERROR(__xludf.DUMMYFUNCTION("SPARKLINE(CHOOSE(MATCH(H4, Motore!$C$1:$M$1, 0), Motore!AA2:AA21, Motore!AB2:AB21, Motore!AC2:AC21, Motore!AD2:AD21, Motore!AE2:AE21, Motore!AF2:AF21, Motore!AG2:AG21, Motore!AH2:AH21, Motore!AI2:AI21, Motore!AJ2:AJ21, Motore!AK2:AK21), {"""&"charttype"",""line""; ""linewidth"",2; ""color"",IF(R4>0.01, ""#008000"", IF(R4<-0.01, ""#FF0000"", ""#FFFF00""))})"),"")
H5: XLY | I5: =D21-$D$31 -> 0.38 | J5: =(E21-$E$31) -> 0.016469991 | K5: =(F21-$F$31) -> 0.010413347 | L5: =(G21-$G$31) -> 0.015663866 | M5: =(H21-$H$31) -> 0.0066832039 | N5: =(J21-$J$31) -> -0.063055354 | O5: =(N5*0.15)+(M5*0.25)+(L5*0.3)+(K5*0.2)+(J5*0.1) -> 0.00064132609 | P5: =COUNTIF(I5:M5, ">0") -> 5 | Q5: =RANK(O5, $O$4:$O$14) -> 7 | R5: =IFERROR(HLOOKUP("RS-Mom " & H5, Motore!$AA$1:$AK$2, 2, FALSE), "Dato non trovato") -> -0.019324651 | S5: =IF(O5>0, IF(P5>=4, "LEADER", "IN RECUPERO"), "DEBOLE") -> LEADER | T5: =IF(AND(R5>0.02, S5="IN RECUPERO"), "🔭 ALERT BUY", IF(AND(Q5<=3, P5>=4, R5>0), "🔥 ACCUMULA", IF(AND(Q5<=3, P5>=4, R5<=0), "📈 MANTIENI", IF(AND(Q5>3, P5>=4), "👀 OSSERVA", "❌ EVITA")))) -> 👀 OSSERVA | U5: =IFERROR(__xludf.DUMMYFUNCTION("SPARKLINE(CHOOSE(MATCH(H5, Motore!$C$1:$M$1, 0), Motore!AA3:AA22, Motore!AB3:AB22, Motore!AC3:AC22, Motore!AD3:AD22, Motore!AE3:AE22, Motore!AF3:AF22, Motore!AG3:AG22, Motore!AH3:AH22, Motore!AI3:AI22, Motore!AJ3:AJ22, Motore!AK3:AK22), {"""&"charttype"",""line""; ""linewidth"",2; ""color"",IF(R5>0.01, ""#008000"", IF(R5<-0.01, ""#FF0000"", ""#FFFF00""))})"),"")
H6: XLF | I6: =D22-$D$31 -> -1.42 | J6: =(E22-$E$31) -> -0.019637151 | K6: =(F22-$F$31) -> -0.044282303 | L6: =(G22-$G$31) -> -0.010698082 | M6: =(H22-$H$31) -> -0.082095645 | N6: =(J22-$J$31) -> -0.090000094 | O6: =(N6*0.15)+(M6*0.25)+(L6*0.3)+(K6*0.2)+(J6*0.1) -> -0.048053526 | P6: =COUNTIF(I6:M6, ">0") -> 0 | Q6: =RANK(O6, $O$4:$O$14) -> 9 | R6: =IFERROR(HLOOKUP("RS-Mom " & H6, Motore!$AA$1:$AK$2, 2, FALSE), "Dato non trovato") -> -0.022039631 | S6: =IF(O6>0, IF(P6>=4, "LEADER", "IN RECUPERO"), "DEBOLE") -> DEBOLE | T6: =IF(AND(R6>0.02, S6="IN RECUPERO"), "🔭 ALERT BUY", IF(AND(Q6<=3, P6>=4, R6>0), "🔥 ACCUMULA", IF(AND(Q6<=3, P6>=4, R6<=0), "📈 MANTIENI", IF(AND(Q6>3, P6>=4), "👀 OSSERVA", "❌ EVITA")))) -> ❌ EVITA | U6: =IFERROR(__xludf.DUMMYFUNCTION("SPARKLINE(CHOOSE(MATCH(H6, Motore!$C$1:$M$1, 0), Motore!AA4:AA23, Motore!AB4:AB23, Motore!AC4:AC23, Motore!AD4:AD23, Motore!AE4:AE23, Motore!AF4:AF23, Motore!AG4:AG23, Motore!AH4:AH23, Motore!AI4:AI23, Motore!AJ4:AJ23, Motore!AK4:AK23), {"""&"charttype"",""line""; ""linewidth"",2; ""color"",IF(R6>0.01, ""#008000"", IF(R6<-0.01, ""#FF0000"", ""#FFFF00""))})"),"")
H7: XLC | I7: =D23-$D$31 -> 0.57 | J7: =(E23-$E$31) -> 0.013563487 | K7: =(F23-$F$31) -> -0.0069969842 | L7: =(G23-$G$31) -> -0.0075298447 | M7: =(H23-$H$31) -> 0.01057999 | N7: =(J23-$J$31) -> 0.03116631 | O7: =(N7*0.15)+(M7*0.25)+(L7*0.3)+(K7*0.2)+(J7*0.1) -> 0.0050179425 | P7: =COUNTIF(I7:M7, ">0") -> 3 | Q7: =RANK(O7, $O$4:$O$14) -> 5 | R7: =IFERROR(HLOOKUP("RS-Mom " & H7, Motore!$AA$1:$AK$2, 2, FALSE), "Dato non trovato") -> -0.029163025 | S7: =IF(O7>0, IF(P7>=4, "LEADER", "IN RECUPERO"), "DEBOLE") -> IN RECUPERO | T7: =IF(AND(R7>0.02, S7="IN RECUPERO"), "🔭 ALERT BUY", IF(AND(Q7<=3, P7>=4, R7>0), "🔥 ACCUMULA", IF(AND(Q7<=3, P7>=4, R7<=0), "📈 MANTIENI", IF(AND(Q7>3, P7>=4), "👀 OSSERVA", "❌ EVITA")))) -> ❌ EVITA | U7: =IFERROR(__xludf.DUMMYFUNCTION("SPARKLINE(CHOOSE(MATCH(H7, Motore!$C$1:$M$1, 0), Motore!AA5:AA24, Motore!AB5:AB24, Motore!AC5:AC24, Motore!AD5:AD24, Motore!AE5:AE24, Motore!AF5:AF24, Motore!AG5:AG24, Motore!AH5:AH24, Motore!AI5:AI24, Motore!AJ5:AJ24, Motore!AK5:AK24), {"""&"charttype"",""line""; ""linewidth"",2; ""color"",IF(R7>0.01, ""#008000"", IF(R7<-0.01, ""#FF0000"", ""#FFFF00""))})"),"")
H8: XLV | I8: =D24-$D$31 -> -0.55 | J8: =(E24-$E$31) -> -0.0038087283 | K8: =(F24-$F$31) -> 0.010728244 | L8: =(G24-$G$31) -> 0.070080755 | M8: =(H24-$H$31) -> 0.081922391 | N8: =(J24-$J$31) -> -0.042396044 | O8: =(N8*0.15)+(M8*0.25)+(L8*0.3)+(K8*0.2)+(J8*0.1) -> 0.036910193 | P8: =COUNTIF(I8:M8, ">0") -> 3 | Q8: =RANK(O8, $O$4:$O$14) -> 3 | R8: =IFERROR(HLOOKUP("RS-Mom " & H8, Motore!$AA$1:$AK$2, 2, FALSE), "Dato non trovato") -> -0.027369692 | S8: =IF(O8>0, IF(P8>=4, "LEADER", "IN RECUPERO"), "DEBOLE") -> IN RECUPERO | T8: =IF(AND(R8>0.02, S8="IN RECUPERO"), "🔭 ALERT BUY", IF(AND(Q8<=3, P8>=4, R8>0), "🔥 ACCUMULA", IF(AND(Q8<=3, P8>=4, R8<=0), "📈 MANTIENI", IF(AND(Q8>3, P8>=4), "👀 OSSERVA", "❌ EVITA")))) -> ❌ EVITA | U8: =IFERROR(__xludf.DUMMYFUNCTION("SPARKLINE(CHOOSE(MATCH(H8, Motore!$C$1:$M$1, 0), Motore!AA6:AA25, Motore!AB6:AB25, Motore!AC6:AC25, Motore!AD6:AD25, Motore!AE6:AE25, Motore!AF6:AF25, Motore!AG6:AG25, Motore!AH6:AH25, Motore!AI6:AI25, Motore!AJ6:AJ25, Motore!AK6:AK25), {"""&"charttype"",""line""; ""linewidth"",2; ""color"",IF(R8>0.01, ""#008000"", IF(R8<-0.01, ""#FF0000"", ""#FFFF00""))})"),"")
H9: XLP | I9: =D25-$D$31 -> 0.74 | J9: =(E25-$E$31) -> -0.010515543 | K9: =(F25-$F$31) -> 0.061388112 | L9: =(G25-$G$31) -> 0.040756369 | M9: =(H25-$H$31) -> -0.054200777 | N9: =(J25-$J$31) -> -0.069344689 | O9: =(N9*0.15)+(M9*0.25)+(L9*0.3)+(K9*0.2)+(J9*0.1) -> -0.00049891884 | P9: =COUNTIF(I9:M9, ">0") -> 3 | Q9: =RANK(O9, $O$4:$O$14) -> 8 | R9: =IFERROR(HLOOKUP("RS-Mom " & H9, Motore!$AA$1:$AK$2, 2, FALSE), "Dato non trovato") -> -0.023651654 | S9: =IF(O9>0, IF(P9>=4, "LEADER", "IN RECUPERO"), "DEBOLE") -> DEBOLE | T9: =IF(AND(R9>0.02, S9="IN RECUPERO"), "🔭 ALERT BUY", IF(AND(Q9<=3, P9>=4, R9>0), "🔥 ACCUMULA", IF(AND(Q9<=3, P9>=4, R9<=0), "📈 MANTIENI", IF(AND(Q9>3, P9>=4), "👀 OSSERVA", "❌ EVITA")))) -> ❌ EVITA | U9: =IFERROR(__xludf.DUMMYFUNCTION("SPARKLINE(CHOOSE(MATCH(H9, Motore!$C$1:$M$1, 0), Motore!AA7:AA26, Motore!AB7:AB26, Motore!AC7:AC26, Motore!AD7:AD26, Motore!AE7:AE26, Motore!AF7:AF26, Motore!AG7:AG26, Motore!AH7:AH26, Motore!AI7:AI26, Motore!AJ7:AJ26, Motore!AK7:AK26), {"""&"charttype"",""line""; ""linewidth"",2; ""color"",IF(R9>0.01, ""#008000"", IF(R9<-0.01, ""#FF0000"", ""#FFFF00""))})"),"")
H10: XLI | I10: =D26-$D$31 -> -0.81 | J10: =(E26-$E$31) -> -0.012974132 | K10: =(F26-$F$31) -> 0.046154553 | L10: =(G26-$G$31) -> 0.048288526 | M10: =(H26-$H$31) -> -0.019251816 | N10: =(J26-$J$31) -> 0.030445017 | O10: =(N10*0.15)+(M10*0.25)+(L10*0.3)+(K10*0.2)+(J10*0.1) -> 0.022173854 | P10: =COUNTIF(I10:M10, ">0") -> 2 | Q10: =RANK(O10, $O$4:$O$14) -> 4 | R10: =IFERROR(HLOOKUP("RS-Mom " & H10, Motore!$AA$1:$AK$2, 2, FALSE), "Dato non trovato") -> 0.009345775 | S10: =IF(O10>0, IF(P10>=4, "LEADER", "IN RECUPERO"), "DEBOLE") -> IN RECUPERO | T10: =IF(AND(R10>0.02, S10="IN RECUPERO"), "🔭 ALERT BUY", IF(AND(Q10<=3, P10>=4, R10>0), "🔥 ACCUMULA", IF(AND(Q10<=3, P10>=4, R10<=0), "📈 MANTIENI", IF(AND(Q10>3, P10>=4), "👀 OSSERVA", "❌ EVITA")))) -> ❌ EVITA | U10: =IFERROR(__xludf.DUMMYFUNCTION("SPARKLINE(CHOOSE(MATCH(H10, Motore!$C$1:$M$1, 0), Motore!AA8:AA27, Motore!AB8:AB27, Motore!AC8:AC27, Motore!AD8:AD27, Motore!AE8:AE27, Motore!AF8:AF27, Motore!AG8:AG27, Motore!AH8:AH27, Motore!AI8:AI27, Motore!AJ8:AJ27, Motore!AK8:AK27), {"&"""charttype"",""line""; ""linewidth"",2; ""color"",IF(R10>0.01, ""#008000"", IF(R10<-0.01, ""#FF0000"", ""#FFFF00""))})"),"")
H11: XLE | I11: =D27-$D$31 -> 0.53 | J11: =(E27-$E$31) -> 0.01620982 | K11: =(F27-$F$31) -> 0.11446044 | L11: =(G27-$G$31) -> 0.10858592 | M11: =(H27-$H$31) -> 0.03458994 | N11: =(J27-$J$31) -> -0.056347354 | O11: =(N11*0.15)+(M11*0.25)+(L11*0.3)+(K11*0.2)+(J11*0.1) -> 0.057284229 | P11: =COUNTIF(I11:M11, ">0") -> 5 | Q11: =RANK(O11, $O$4:$O$14) -> 1 | R11: =IFERROR(HLOOKUP("RS-Mom " & H11, Motore!$AA$1:$AK$2, 2, FALSE), "Dato non trovato") -> 0.031449573 | S11: =IF(O11>0, IF(P11>=4, "LEADER", "IN RECUPERO"), "DEBOLE") -> LEADER | T11: =IF(AND(R11>0.02, S11="IN RECUPERO"), "🔭 ALERT BUY", IF(AND(Q11<=3, P11>=4, R11>0), "🔥 ACCUMULA", IF(AND(Q11<=3, P11>=4, R11<=0), "📈 MANTIENI", IF(AND(Q11>3, P11>=4), "👀 OSSERVA", "❌ EVITA")))) -> 🔥 ACCUMULA | U11: =IFERROR(__xludf.DUMMYFUNCTION("SPARKLINE(CHOOSE(MATCH(H11, Motore!$C$1:$M$1, 0), Motore!AA9:AA28, Motore!AB9:AB28, Motore!AC9:AC28, Motore!AD9:AD28, Motore!AE9:AE28, Motore!AF9:AF28, Motore!AG9:AG28, Motore!AH9:AH28, Motore!AI9:AI28, Motore!AJ9:AJ28, Motore!AK9:AK28), {"&"""charttype"",""line""; ""linewidth"",2; ""color"",IF(R11>0.01, ""#008000"", IF(R11<-0.01, ""#FF0000"", ""#FFFF00""))})"),"")
H12: XLB | I12: =D28-$D$31 -> 0.87 | J12: =(E28-$E$31) -> 0.019743582 | K12: =(F28-$F$31) -> 0.085277375 | L12: =(G28-$G$31) -> 0.11735097 | M12: =(H28-$H$31) -> 0.015663582 | N12: =(J28-$J$31) -> -0.010736562 | O12: =(N12*0.15)+(M12*0.25)+(L12*0.3)+(K12*0.2)+(J12*0.1) -> 0.056540535 | P12: =COUNTIF(I12:M12, ">0") -> 5 | Q12: =RANK(O12, $O$4:$O$14) -> 2 | R12: =IFERROR(HLOOKUP("RS-Mom " & H12, Motore!$AA$1:$AK$2, 2, FALSE), "Dato non trovato") -> -0.0078861614 | S12: =IF(O12>0, IF(P12>=4, "LEADER", "IN RECUPERO"), "DEBOLE") -> LEADER | T12: =IF(AND(R12>0.02, S12="IN RECUPERO"), "🔭 ALERT BUY", IF(AND(Q12<=3, P12>=4, R12>0), "🔥 ACCUMULA", IF(AND(Q12<=3, P12>=4, R12<=0), "📈 MANTIENI", IF(AND(Q12>3, P12>=4), "👀 OSSERVA", "❌ EVITA")))) -> 📈 MANTIENI | U12: =IFERROR(__xludf.DUMMYFUNCTION("SPARKLINE(CHOOSE(MATCH(H12, Motore!$C$1:$M$1, 0), Motore!AA10:AA29, Motore!AB10:AB29, Motore!AC10:AC29, Motore!AD10:AD29, Motore!AE10:AE29, Motore!AF10:AF29, Motore!AG10:AG29, Motore!AH10:AH29, Motore!AI10:AI29, Motore!AJ10:AJ29, Motore!AK10:A"&"K29), {""charttype"",""line""; ""linewidth"",2; ""color"",IF(R12>0.01, ""#008000"", IF(R12<-0.01, ""#FF0000"", ""#FFFF00""))})"),"")
H13: XLU | I13: =D29-$D$31 -> -0.39 | J13: =(E29-$E$31) -> -0.026504529 | K13: =(F29-$F$31) -> -0.0035780755 | L13: =(G29-$G$31) -> -0.076970748 | M13: =(H29-$H$31) -> -0.064157353 | N13: =(J29-$J$31) -> -0.062696663 | O13: =(N13*0.15)+(M13*0.25)+(L13*0.3)+(K13*0.2)+(J13*0.1) -> -0.05190113 | P13: =COUNTIF(I13:M13, ">0") -> 0 | Q13: =RANK(O13, $O$4:$O$14) -> 10 | R13: =IFERROR(HLOOKUP("RS-Mom " & H13, Motore!$AA$1:$AK$2, 2, FALSE), "Dato non trovato") -> 0.010220977 | S13: =IF(O13>0, IF(P13>=4, "LEADER", "IN RECUPERO"), "DEBOLE") -> DEBOLE | T13: =IF(AND(R13>0.02, S13="IN RECUPERO"), "🔭 ALERT BUY", IF(AND(Q13<=3, P13>=4, R13>0), "🔥 ACCUMULA", IF(AND(Q13<=3, P13>=4, R13<=0), "📈 MANTIENI", IF(AND(Q13>3, P13>=4), "👀 OSSERVA", "❌ EVITA")))) -> ❌ EVITA | U13: =IFERROR(__xludf.DUMMYFUNCTION("SPARKLINE(CHOOSE(MATCH(H13, Motore!$C$1:$M$1, 0), Motore!AA11:AA30, Motore!AB11:AB30, Motore!AC11:AC30, Motore!AD11:AD30, Motore!AE11:AE30, Motore!AF11:AF30, Motore!AG11:AG30, Motore!AH11:AH30, Motore!AI11:AI30, Motore!AJ11:AJ30, Motore!AK11:A"&"K30), {""charttype"",""line""; ""linewidth"",2; ""color"",IF(R13>0.01, ""#008000"", IF(R13<-0.01, ""#FF0000"", ""#FFFF00""))})"),"")
H14: XLRE | I14: =D30-$D$31 -> 0.23 | J14: =(E30-$E$31) -> -0.02081673 | K14: =(F30-$F$31) -> 0.019580309 | L14: =(G30-$G$31) -> -0.040684733 | M14: =(H30-$H$31) -> -0.10112062 | N14: =(J30-$J$31) -> -0.14087813 | O14: =(N14*0.15)+(M14*0.25)+(L14*0.3)+(K14*0.2)+(J14*0.1) -> -0.056782904 | P14: =COUNTIF(I14:M14, ">0") -> 2 | Q14: =RANK(O14, $O$4:$O$14) -> 11 | R14: =IFERROR(HLOOKUP("RS-Mom " & H14, Motore!$AA$1:$AK$2, 2, FALSE), "Dato non trovato") -> -0.007008799 | S14: =IF(O14>0, IF(P14>=4, "LEADER", "IN RECUPERO"), "DEBOLE") -> DEBOLE | T14: =IF(AND(R14>0.02, S14="IN RECUPERO"), "🔭 ALERT BUY", IF(AND(Q14<=3, P14>=4, R14>0), "🔥 ACCUMULA", IF(AND(Q14<=3, P14>=4, R14<=0), "📈 MANTIENI", IF(AND(Q14>3, P14>=4), "👀 OSSERVA", "❌ EVITA")))) -> ❌ EVITA | U14: =IFERROR(__xludf.DUMMYFUNCTION("SPARKLINE(CHOOSE(MATCH(H14, Motore!$C$1:$M$1, 0), Motore!AA12:AA31, Motore!AB12:AB31, Motore!AC12:AC31, Motore!AD12:AD31, Motore!AE12:AE31, Motore!AF12:AF31, Motore!AG12:AG31, Motore!AH12:AH31, Motore!AI12:AI31, Motore!AJ12:AJ31, Motore!AK12:A"&"K31), {""charttype"",""line""; ""linewidth"",2; ""color"",IF(R14>0.01, ""#008000"", IF(R14<-0.01, ""#FF0000"", ""#FFFF00""))})"),"")
H15: SPY | I15: =D31-$D$31 -> 0 | J15: =(E31-$E$31) -> 0 | K15: =(F31-$F$31) -> 0 | L15: =(G31-$G$31) -> 0 | M15: =(H31-$H$31) -> 0 | N15: =(J31-$J$31) -> 0
A19: ticker | B19: Nome Etf | C19: Prezzo corrente | D19: Var. % giornaliera | E19: Var. % settimanale | F19: Var. % mensile | G19: Var. % trimestrale | H19: Var.%semestrale | I19: Var. % Ytd | J19: Var. % annuale | K19: Var. % 2 anni | L19: Var. % 3 anni | M19: Var. % 5 anni | N19: Var.% 10 anni | O19: Var. % 20 anni
A20: XLK | B20: =IFERROR(__xludf.DUMMYFUNCTION("GOOGLEFINANCE(A20,""name"")"),"State Street Technology Select Sector SPDR ETF") -> State Street Technology Select Sector SPDR ETF | C20: =IFERROR(__xludf.DUMMYFUNCTION("GOOGLEFINANCE(A20,""price"")"),145.09) -> 145.09 | D20: =IFERROR(__xludf.DUMMYFUNCTION("GOOGLEFINANCE(A20,""changepct"")"),0.14) -> 0.14 | E20: =IFERROR(__xludf.DUMMYFUNCTION(" ((GOOGLEFINANCE(A20,""price"") - INDEX(GOOGLEFINANCE(A20,""price"",TODAY()-7),2,2)) / INDEX(GOOGLEFINANCE(A20,""price"",TODAY()-7),2,2)) "),0.022913141567963903) -> 0.022913142 | F20: =IFERROR(__xludf.DUMMYFUNCTION(" ((GOOGLEFINANCE(A20,""price"") - INDEX(GOOGLEFINANCE(A20,""price"",TODAY()-30),2,2)) / INDEX(GOOGLEFINANCE(A20,""price"",TODAY()-30),2,2)) "),-0.00982733911144474) -> -0.0098273391 | G20: =IFERROR(__xludf.DUMMYFUNCTION(" ((GOOGLEFINANCE(A20,""price"") - INDEX(GOOGLEFINANCE(A20,""price"",TODAY()-90),2,2)) / INDEX(GOOGLEFINANCE(A20,""price"",TODAY()-90),2,2))"),-0.0294983277591973) -> -0.029498328 | H20: =IFERROR(__xludf.DUMMYFUNCTION(" ((GOOGLEFINANCE(A20,""price"") - INDEX(GOOGLEFINANCE(A20,""price"",TODAY()-182),2,2)) / INDEX(GOOGLEFINANCE(A20,""price"",TODAY()-182),2,2))"),0.09883368676158749) -> 0.098833687 | I20: =IFERROR(__xludf.DUMMYFUNCTION("(GOOGLEFINANCE(A20,""price"")-INDEX(GOOGLEFINANCE(A20,""price"",""01-01-""&YEAR(TODAY())),2,2))/INDEX(GOOGLEFINANCE(A20,""price"",""01-01-""&YEAR(TODAY())),2,2)"),0.005474705474705419) -> 0.0054747055 | J20: =IFERROR(__xludf.DUMMYFUNCTION(" ((GOOGLEFINANCE(A20,""price"") - INDEX(GOOGLEFINANCE(A20,""price"",TODAY()-365),2,2)) / INDEX(GOOGLEFINANCE(A20,""price"",TODAY()-365),2,2)) "),0.21262014208106975) -> 0.21262014 | K20: =IFERROR(__xludf.DUMMYFUNCTION(" ((GOOGLEFINANCE(A20,""price"") - INDEX(GOOGLEFINANCE(A20,""price"",TODAY()-730),2,2)) / INDEX(GOOGLEFINANCE(A20,""price"",TODAY()-730),2,2))"),0.4217540421362078) -> 0.42175404 | L20: =IFERROR(__xludf.DUMMYFUNCTION(" ((GOOGLEFINANCE(A20,""price"") - INDEX(GOOGLEFINANCE(A20,""price"",TODAY()-1095),2,2)) / INDEX(GOOGLEFINANCE(A20,""price"",TODAY()-1095),2,2))"),1.1655223880597017) -> 1.1655224 | M20: =IFERROR(__xludf.DUMMYFUNCTION(" ((GOOGLEFINANCE(A20,""price"") - INDEX(GOOGLEFINANCE(A20,""price"",TODAY()-1825),2,2)) / INDEX(GOOGLEFINANCE(A20,""price"",TODAY()-1825),2,2))"),1.166492459310139) -> 1.1664925 | N20: =IFERROR(__xludf.DUMMYFUNCTION(" ((GOOGLEFINANCE(A20,""price"") - INDEX(GOOGLEFINANCE(A20,""price"",TODAY()-3650),2,2)) / INDEX(GOOGLEFINANCE(A20,""price"",TODAY()-3650),2,2))"),6.3500506585612975) -> 6.3500507 | O20: =IFERROR(__xludf.DUMMYFUNCTION(" ((GOOGLEFINANCE(A20,""price"") - INDEX(GOOGLEFINANCE(A20,""price"",TODAY()-7300),2,2)) / INDEX(GOOGLEFINANCE(A20,""price"",TODAY()-7300),2,2))"),12.323232323232322) -> 12.323232
A21: XLY | B21: =IFERROR(__xludf.DUMMYFUNCTION("GOOGLEFINANCE(A21,""name"")"),"State Street Cons Disc Sel Sect SPDR Income ETF") -> State Street Cons Disc Sel Sect SPDR Income ETF | C21: =IFERROR(__xludf.DUMMYFUNCTION("GOOGLEFINANCE(A21,""price"")"),123.13) -> 123.13 | D21: =IFERROR(__xludf.DUMMYFUNCTION("GOOGLEFINANCE(A21,""changepct"")"),0.42) -> 0.42 | E21: =IFERROR(__xludf.DUMMYFUNCTION(" ((GOOGLEFINANCE(A21,""price"") - INDEX(GOOGLEFINANCE(A21,""price"",TODAY()-7),2,2)) / INDEX(GOOGLEFINANCE(A21,""price"",TODAY()-7),2,2)) "),0.03366353257219603) -> 0.033663533 | F21: =IFERROR(__xludf.DUMMYFUNCTION(" ((GOOGLEFINANCE(A21,""price"") - INDEX(GOOGLEFINANCE(A21,""price"",TODAY()-30),2,2)) / INDEX(GOOGLEFINANCE(A21,""price"",TODAY()-30),2,2)) "),0.008848832445718954) -> 0.0088488324 | G21: =IFERROR(__xludf.DUMMYFUNCTION(" ((GOOGLEFINANCE(A21,""price"") - INDEX(GOOGLEFINANCE(A21,""price"",TODAY()-90),2,2)) / INDEX(GOOGLEFINANCE(A21,""price"",TODAY()-90),2,2))"),0.02148664343786286) -> 0.021486643 | H21: =IFERROR(__xludf.DUMMYFUNCTION(" ((GOOGLEFINANCE(A21,""price"") - INDEX(GOOGLEFINANCE(A21,""price"",TODAY()-182),2,2)) / INDEX(GOOGLEFINANCE(A21,""price"",TODAY()-182),2,2))"),0.0887788487045715) -> 0.088778849 | I21: =IFERROR(__xludf.DUMMYFUNCTION("(GOOGLEFINANCE(A21,""price"")-INDEX(GOOGLEFINANCE(A21,""price"",""01-01-""&YEAR(TODAY())),2,2))/INDEX(GOOGLEFINANCE(A21,""price"",""01-01-""&YEAR(TODAY())),2,2)"),0.04038867765103508) -> 0.040388678 | J21: =IFERROR(__xludf.DUMMYFUNCTION(" ((GOOGLEFINANCE(A21,""price"") - INDEX(GOOGLEFINANCE(A21,""price"",TODAY()-365),2,2)) / INDEX(GOOGLEFINANCE(A21,""price"",TODAY()-365),2,2)) "),0.07060255629945214) -> 0.070602556 | K21: =IFERROR(__xludf.DUMMYFUNCTION(" ((GOOGLEFINANCE(A21,""price"") - INDEX(GOOGLEFINANCE(A21,""price"",TODAY()-730),2,2)) / INDEX(GOOGLEFINANCE(A21,""price"",TODAY()-730),2,2))"),0.4409596255119952) -> 0.44095963 | L21: =IFERROR(__xludf.DUMMYFUNCTION(" ((GOOGLEFINANCE(A21,""price"") - INDEX(GOOGLEFINANCE(A21,""price"",TODAY()-1095),2,2)) / INDEX(GOOGLEFINANCE(A21,""price"",TODAY()-1095),2,2))"),0.7376517075924357) -> 0.73765171 | M21: =IFERROR(__xludf.DUMMYFUNCTION(" ((GOOGLEFINANCE(A21,""price"") - INDEX(GOOGLEFINANCE(A21,""price"",TODAY()-1825),2,2)) / INDEX(GOOGLEFINANCE(A21,""price"",TODAY()-1825),2,2))"),0.4423099449455311) -> 0.44230994 | N21: =IFERROR(__xludf.DUMMYFUNCTION(" ((GOOGLEFINANCE(A21,""price"") - INDEX(GOOGLEFINANCE(A21,""price"",TODAY()-3650),2,2)) / INDEX(GOOGLEFINANCE(A21,""price"",TODAY()-3650),2,2))"),2.402321083172147) -> 2.4023211 | O21: =IFERROR(__xludf.DUMMYFUNCTION(" ((GOOGLEFINANCE(A21,""price"") - INDEX(GOOGLEFINANCE(A21,""price"",TODAY()-7300),2,2)) / INDEX(GOOGLEFINANCE(A21,""price"",TODAY()-7300),2,2))"),6.381894484412469) -> 6.3818945
A22: XLF | B22: =IFERROR(__xludf.DUMMYFUNCTION("GOOGLEFINANCE(A22,""name"")"),"State Street Financial Sel Sec SPDR ETF") -> State Street Financial Sel Sec SPDR ETF | C22: =IFERROR(__xludf.DUMMYFUNCTION("GOOGLEFINANCE(A22,""price"")"),53.07) -> 53.07 | D22: =IFERROR(__xludf.DUMMYFUNCTION("GOOGLEFINANCE(A22,""changepct"")"),-1.38) -> -1.38 | E22: =IFERROR(__xludf.DUMMYFUNCTION(" ((GOOGLEFINANCE(A22,""price"") - INDEX(GOOGLEFINANCE(A22,""price"",TODAY()-7),2,2)) / INDEX(GOOGLEFINANCE(A22,""price"",TODAY()-7),2,2)) "),-0.0024436090225564387) -> -0.002443609 | F22: =IFERROR(__xludf.DUMMYFUNCTION(" ((GOOGLEFINANCE(A22,""price"") - INDEX(GOOGLEFINANCE(A22,""price"",TODAY()-30),2,2)) / INDEX(GOOGLEFINANCE(A22,""price"",TODAY()-30),2,2)) "),-0.04584681769147784) -> -0.045846818 | G22: =IFERROR(__xludf.DUMMYFUNCTION(" ((GOOGLEFINANCE(A22,""price"") - INDEX(GOOGLEFINANCE(A22,""price"",TODAY()-90),2,2)) / INDEX(GOOGLEFINANCE(A22,""price"",TODAY()-90),2,2))"),-0.004875304706544122) -> -0.0048753047 | H22: =IFERROR(__xludf.DUMMYFUNCTION(" ((GOOGLEFINANCE(A22,""price"") - INDEX(GOOGLEFINANCE(A22,""price"",TODAY()-182),2,2)) / INDEX(GOOGLEFINANCE(A22,""price"",TODAY()-182),2,2))"),0.0) -> 0 | I22: =IFERROR(__xludf.DUMMYFUNCTION("(GOOGLEFINANCE(A22,""price"")-INDEX(GOOGLEFINANCE(A22,""price"",""01-01-""&YEAR(TODAY())),2,2))/INDEX(GOOGLEFINANCE(A22,""price"",""01-01-""&YEAR(TODAY())),2,2)"),-0.033861277990169296) -> -0.033861278 | J22: =IFERROR(__xludf.DUMMYFUNCTION(" ((GOOGLEFINANCE(A22,""price"") - INDEX(GOOGLEFINANCE(A22,""price"",TODAY()-365),2,2)) / INDEX(GOOGLEFINANCE(A22,""price"",TODAY()-365),2,2)) "),0.04365781710914452) -> 0.043657817 | K22: =IFERROR(__xludf.DUMMYFUNCTION(" ((GOOGLEFINANCE(A22,""price"") - INDEX(GOOGLEFINANCE(A22,""price"",TODAY()-730),2,2)) / INDEX(GOOGLEFINANCE(A22,""price"",TODAY()-730),2,2))"),0.3780836146455467) -> 0.37808361 | L22: =IFERROR(__xludf.DUMMYFUNCTION(" ((GOOGLEFINANCE(A22,""price"") - INDEX(GOOGLEFINANCE(A22,""price"",TODAY()-1095),2,2)) / INDEX(GOOGLEFINANCE(A22,""price"",TODAY()-1095),2,2))"),0.4717138103161397) -> 0.47171381 | M22: =IFERROR(__xludf.DUMMYFUNCTION(" ((GOOGLEFINANCE(A22,""price"") - INDEX(GOOGLEFINANCE(A22,""price"",TODAY()-1825),2,2)) / INDEX(GOOGLEFINANCE(A22,""price"",TODAY()-1825),2,2))"),0.7619521912350598) -> 0.76195219 | N22: =IFERROR(__xludf.DUMMYFUNCTION(" ((GOOGLEFINANCE(A22,""price"") - INDEX(GOOGLEFINANCE(A22,""price"",TODAY()-3650),2,2)) / INDEX(GOOGLEFINANCE(A22,""price"",TODAY()-3650),2,2))"),2.809763101220388) -> 2.8097631 | O22: =IFERROR(__xludf.DUMMYFUNCTION(" ((GOOGLEFINANCE(A22,""price"") - INDEX(GOOGLEFINANCE(A22,""price"",TODAY()-7300),2,2)) / INDEX(GOOGLEFINANCE(A22,""price"",TODAY()-7300),2,2))"),1.5092198581560285) -> 1.5092199
A23: XLC | B23: =IFERROR(__xludf.DUMMYFUNCTION("GOOGLEFINANCE(A23,""name"")"),"State Street Com Svc Sel Sec SPDR ETF") -> State Street Com Svc Sel Sec SPDR ETF | C23: =IFERROR(__xludf.DUMMYFUNCTION("GOOGLEFINANCE(A23,""price"")"),116.96) -> 116.96 | D23: =IFERROR(__xludf.DUMMYFUNCTION("GOOGLEFINANCE(A23,""changepct"")"),0.61) -> 0.61 | E23: =IFERROR(__xludf.DUMMYFUNCTION(" ((GOOGLEFINANCE(A23,""price"") - INDEX(GOOGLEFINANCE(A23,""price"",TODAY()-7),2,2)) / INDEX(GOOGLEFINANCE(A23,""price"",TODAY()-7),2,2)) "),0.03075702828941566) -> 0.030757028 | F23: =IFERROR(__xludf.DUMMYFUNCTION(" ((GOOGLEFINANCE(A23,""price"") - INDEX(GOOGLEFINANCE(A23,""price"",TODAY()-30),2,2)) / INDEX(GOOGLEFINANCE(A23,""price"",TODAY()-30),2,2)) "),-0.008561498686106681) -> -0.0085614987 | G23: =IFERROR(__xludf.DUMMYFUNCTION(" ((GOOGLEFINANCE(A23,""price"") - INDEX(GOOGLEFINANCE(A23,""price"",TODAY()-90),2,2)) / INDEX(GOOGLEFINANCE(A23,""price"",TODAY()-90),2,2))"),-0.0017070672584500073) -> -0.0017070673 | H23: =IFERROR(__xludf.DUMMYFUNCTION(" ((GOOGLEFINANCE(A23,""price"") - INDEX(GOOGLEFINANCE(A23,""price"",TODAY()-182),2,2)) / INDEX(GOOGLEFINANCE(A23,""price"",TODAY()-182),2,2))"),0.09267563527653201) -> 0.092675635 | I23: =IFERROR(__xludf.DUMMYFUNCTION("(GOOGLEFINANCE(A23,""price"")-INDEX(GOOGLEFINANCE(A23,""price"",""01-01-""&YEAR(TODAY())),2,2))/INDEX(GOOGLEFINANCE(A23,""price"",""01-01-""&YEAR(TODAY())),2,2)"),5.132591958938243E-4) -> 0.0005132592 | J23: =IFERROR(__xludf.DUMMYFUNCTION(" ((GOOGLEFINANCE(A23,""price"") - INDEX(GOOGLEFINANCE(A23,""price"",TODAY()-365),2,2)) / INDEX(GOOGLEFINANCE(A23,""price"",TODAY()-365),2,2)) "),0.16482422069514988) -> 0.16482422 | K23: =IFERROR(__xludf.DUMMYFUNCTION(" ((GOOGLEFINANCE(A23,""price"") - INDEX(GOOGLEFINANCE(A23,""price"",TODAY()-730),2,2)) / INDEX(GOOGLEFINANCE(A23,""price"",TODAY()-730),2,2))"),0.5105256360583751) -> 0.51052564 | L23: =IFERROR(__xludf.DUMMYFUNCTION(" ((GOOGLEFINANCE(A23,""price"") - INDEX(GOOGLEFINANCE(A23,""price"",TODAY()-1095),2,2)) / INDEX(GOOGLEFINANCE(A23,""price"",TODAY()-1095),2,2))"),1.1631218790456814) -> 1.1631219 | M23: =IFERROR(__xludf.DUMMYFUNCTION(" ((GOOGLEFINANCE(A23,""price"") - INDEX(GOOGLEFINANCE(A23,""price"",TODAY()-1825),2,2)) / INDEX(GOOGLEFINANCE(A23,""price"",TODAY()-1825),2,2))"),0.6891969959560947) -> 0.689197
A24: XLV | B24: =IFERROR(__xludf.DUMMYFUNCTION("GOOGLEFINANCE(A24,""name"")"),"State Street Health Care Select Sector SPDR ETF") -> State Street Health Care Select Sector SPDR ETF | C24: =IFERROR(__xludf.DUMMYFUNCTION("GOOGLEFINANCE(A24,""price"")"),157.48) -> 157.48 | D24: =IFERROR(__xludf.DUMMYFUNCTION("GOOGLEFINANCE(A24,""changepct"")"),-0.51) -> -0.51 | E24: =IFERROR(__xludf.DUMMYFUNCTION(" ((GOOGLEFINANCE(A24,""price"") - INDEX(GOOGLEFINANCE(A24,""price"",TODAY()-7),2,2)) / INDEX(GOOGLEFINANCE(A24,""price"",TODAY()-7),2,2)) "),0.013384813384813283) -> 0.013384813 | F24: =IFERROR(__xludf.DUMMYFUNCTION(" ((GOOGLEFINANCE(A24,""price"") - INDEX(GOOGLEFINANCE(A24,""price"",TODAY()-30),2,2)) / INDEX(GOOGLEFINANCE(A24,""price"",TODAY()-30),2,2)) "),0.009163729573854395) -> 0.0091637296 | G24: =IFERROR(__xludf.DUMMYFUNCTION(" ((GOOGLEFINANCE(A24,""price"") - INDEX(GOOGLEFINANCE(A24,""price"",TODAY()-90),2,2)) / INDEX(GOOGLEFINANCE(A24,""price"",TODAY()-90),2,2))"),0.07590353214456504) -> 0.075903532 | H24: =IFERROR(__xludf.DUMMYFUNCTION(" ((GOOGLEFINANCE(A24,""price"") - INDEX(GOOGLEFINANCE(A24,""price"",TODAY()-182),2,2)) / INDEX(GOOGLEFINANCE(A24,""price"",TODAY()-182),2,2))"),0.16401803533151008) -> 0.16401804 | I24: =IFERROR(__xludf.DUMMYFUNCTION("(GOOGLEFINANCE(A24,""price"")-INDEX(GOOGLEFINANCE(A24,""price"",""01-01-""&YEAR(TODAY())),2,2))/INDEX(GOOGLEFINANCE(A24,""price"",""01-01-""&YEAR(TODAY())),2,2)"),0.012667995627290842) -> 0.012667996 | J24: =IFERROR(__xludf.DUMMYFUNCTION(" ((GOOGLEFINANCE(A24,""price"") - INDEX(GOOGLEFINANCE(A24,""price"",TODAY()-365),2,2)) / INDEX(GOOGLEFINANCE(A24,""price"",TODAY()-365),2,2)) "),0.09126186681449648) -> 0.091261867 | K24: =IFERROR(__xludf.DUMMYFUNCTION(" ((GOOGLEFINANCE(A24,""price"") - INDEX(GOOGLEFINANCE(A24,""price"",TODAY()-730),2,2)) / INDEX(GOOGLEFINANCE(A24,""price"",TODAY()-730),2,2))"),0.1372039283651069) -> 0.13720393 | L24: =IFERROR(__xludf.DUMMYFUNCTION(" ((GOOGLEFINANCE(A24,""price"") - INDEX(GOOGLEFINANCE(A24,""price"",TODAY()-1095),2,2)) / INDEX(GOOGLEFINANCE(A24,""price"",TODAY()-1095),2,2))"),0.1794487717195924) -> 0.17944877 | M24: =IFERROR(__xludf.DUMMYFUNCTION(" ((GOOGLEFINANCE(A24,""price"") - INDEX(GOOGLEFINANCE(A24,""price"",TODAY()-1825),2,2)) / INDEX(GOOGLEFINANCE(A24,""price"",TODAY()-1825),2,2))"),0.33051706657654606) -> 0.33051707 | N24: =IFERROR(__xludf.DUMMYFUNCTION(" ((GOOGLEFINANCE(A24,""price"") - INDEX(GOOGLEFINANCE(A24,""price"",TODAY()-3650),2,2)) / INDEX(GOOGLEFINANCE(A24,""price"",TODAY()-3650),2,2))"),1.3518518518518519) -> 1.3518519 | O24: =IFERROR(__xludf.DUMMYFUNCTION(" ((GOOGLEFINANCE(A24,""price"") - INDEX(GOOGLEFINANCE(A24,""price"",TODAY()-7300),2,2)) / INDEX(GOOGLEFINANCE(A24,""price"",TODAY()-7300),2,2))"),3.8998133167392655) -> 3.8998133
A25: XLP | B25: =IFERROR(__xludf.DUMMYFUNCTION("GOOGLEFINANCE(A25,""name"")"),"State Street Cons Staples Sel Sec SPDR Inc ETF") -> State Street Cons Staples Sel Sec SPDR Inc ETF | C25: =IFERROR(__xludf.DUMMYFUNCTION("GOOGLEFINANCE(A25,""price"")"),82.91) -> 82.91 | D25: =IFERROR(__xludf.DUMMYFUNCTION("GOOGLEFINANCE(A25,""changepct"")"),0.78) -> 0.78 | E25: =IFERROR(__xludf.DUMMYFUNCTION(" ((GOOGLEFINANCE(A25,""price"") - INDEX(GOOGLEFINANCE(A25,""price"",TODAY()-7),2,2)) / INDEX(GOOGLEFINANCE(A25,""price"",TODAY()-7),2,2)) "),0.006677999028654652) -> 0.006677999 | F25: =IFERROR(__xludf.DUMMYFUNCTION(" ((GOOGLEFINANCE(A25,""price"") - INDEX(GOOGLEFINANCE(A25,""price"",TODAY()-30),2,2)) / INDEX(GOOGLEFINANCE(A25,""price"",TODAY()-30),2,2)) "),0.05982359708551697) -> 0.059823597 | G25: =IFERROR(__xludf.DUMMYFUNCTION(" ((GOOGLEFINANCE(A25,""price"") - INDEX(GOOGLEFINANCE(A25,""price"",TODAY()-90),2,2)) / INDEX(GOOGLEFINANCE(A25,""price"",TODAY()-90),2,2))"),0.04657914668013125) -> 0.046579147 | H25: =IFERROR(__xludf.DUMMYFUNCTION(" ((GOOGLEFINANCE(A25,""price"") - INDEX(GOOGLEFINANCE(A25,""price"",TODAY()-182),2,2)) / INDEX(GOOGLEFINANCE(A25,""price"",TODAY()-182),2,2))"),0.02789486734440863) -> 0.027894867 | I25: =IFERROR(__xludf.DUMMYFUNCTION("(GOOGLEFINANCE(A25,""price"")-INDEX(GOOGLEFINANCE(A25,""price"",""01-01-""&YEAR(TODAY())),2,2))/INDEX(GOOGLEFINANCE(A25,""price"",""01-01-""&YEAR(TODAY())),2,2)"),0.06719011455785814) -> 0.067190115 | J25: =IFERROR(__xludf.DUMMYFUNCTION(" ((GOOGLEFINANCE(A25,""price"") - INDEX(GOOGLEFINANCE(A25,""price"",TODAY()-365),2,2)) / INDEX(GOOGLEFINANCE(A25,""price"",TODAY()-365),2,2)) "),0.0643132220795891) -> 0.064313222 | K25: =IFERROR(__xludf.DUMMYFUNCTION(" ((GOOGLEFINANCE(A25,""price"") - INDEX(GOOGLEFINANCE(A25,""price"",TODAY()-730),2,2)) / INDEX(GOOGLEFINANCE(A25,""price"",TODAY()-730),2,2))"),0.14706696181516318) -> 0.14706696 | L25: =IFERROR(__xludf.DUMMYFUNCTION(" ((GOOGLEFINANCE(A25,""price"") - INDEX(GOOGLEFINANCE(A25,""price"",TODAY()-1095),2,2)) / INDEX(GOOGLEFINANCE(A25,""price"",TODAY()-1095),2,2))"),0.13064230192281465) -> 0.1306423 | M25: =IFERROR(__xludf.DUMMYFUNCTION(" ((GOOGLEFINANCE(A25,""price"") - INDEX(GOOGLEFINANCE(A25,""price"",TODAY()-1825),2,2)) / INDEX(GOOGLEFINANCE(A25,""price"",TODAY()-1825),2,2))"),0.26156421180766887) -> 0.26156421 | N25: =IFERROR(__xludf.DUMMYFUNCTION(" ((GOOGLEFINANCE(A25,""price"") - INDEX(GOOGLEFINANCE(A25,""price"",TODAY()-3650),2,2)) / INDEX(GOOGLEFINANCE(A25,""price"",TODAY()-3650),2,2))"),0.6834517766497461) -> 0.68345178 | O25: =IFERROR(__xludf.DUMMYFUNCTION(" ((GOOGLEFINANCE(A25,""price"") - INDEX(GOOGLEFINANCE(A25,""price"",TODAY()-7300),2,2)) / INDEX(GOOGLEFINANCE(A25,""price"",TODAY()-7300),2,2))"),2.537116040955631) -> 2.537116
A26: XLI | B26: =IFERROR(__xludf.DUMMYFUNCTION("GOOGLEFINANCE(A26,""name"")"),"State Street Industrial Select Sector SPDR ETF") -> State Street Industrial Select Sector SPDR ETF | C26: =IFERROR(__xludf.DUMMYFUNCTION("GOOGLEFINANCE(A26,""price"")"),164.22) -> 164.22 | D26: =IFERROR(__xludf.DUMMYFUNCTION("GOOGLEFINANCE(A26,""changepct"")"),-0.77) -> -0.77 | E26: =IFERROR(__xludf.DUMMYFUNCTION(" ((GOOGLEFINANCE(A26,""price"") - INDEX(GOOGLEFINANCE(A26,""price"",TODAY()-7),2,2)) / INDEX(GOOGLEFINANCE(A26,""price"",TODAY()-7),2,2)) "),0.004219409282700408) -> 0.0042194093 | F26: =IFERROR(__xludf.DUMMYFUNCTION(" ((GOOGLEFINANCE(A26,""price"") - INDEX(GOOGLEFINANCE(A26,""price"",TODAY()-30),2,2)) / INDEX(GOOGLEFINANCE(A26,""price"",TODAY()-30),2,2)) "),0.044590038801602894) -> 0.044590039 | G26: =IFERROR(__xludf.DUMMYFUNCTION(" ((GOOGLEFINANCE(A26,""price"") - INDEX(GOOGLEFINANCE(A26,""price"",TODAY()-90),2,2)) / INDEX(GOOGLEFINANCE(A26,""price"",TODAY()-90),2,2))"),0.05411130367802816) -> 0.054111304 | H26: =IFERROR(__xludf.DUMMYFUNCTION(" ((GOOGLEFINANCE(A26,""price"") - INDEX(GOOGLEFINANCE(A26,""price"",TODAY()-182),2,2)) / INDEX(GOOGLEFINANCE(A26,""price"",TODAY()-182),2,2))"),0.06284382887838981) -> 0.062843829 | I26: =IFERROR(__xludf.DUMMYFUNCTION("(GOOGLEFINANCE(A26,""price"")-INDEX(GOOGLEFINANCE(A26,""price"",""01-01-""&YEAR(TODAY())),2,2))/INDEX(GOOGLEFINANCE(A26,""price"",""01-01-""&YEAR(TODAY())),2,2)"),0.03949867071781244) -> 0.039498671 | J26: =IFERROR(__xludf.DUMMYFUNCTION(" ((GOOGLEFINANCE(A26,""price"") - INDEX(GOOGLEFINANCE(A26,""price"",TODAY()-365),2,2)) / INDEX(GOOGLEFINANCE(A26,""price"",TODAY()-365),2,2)) "),0.1641029276245836) -> 0.16410293 | K26: =IFERROR(__xludf.DUMMYFUNCTION(" ((GOOGLEFINANCE(A26,""price"") - INDEX(GOOGLEFINANCE(A26,""price"",TODAY()-730),2,2)) / INDEX(GOOGLEFINANCE(A26,""price"",TODAY()-730),2,2))"),0.4454713493530499) -> 0.44547135 | L26: =IFERROR(__xludf.DUMMYFUNCTION(" ((GOOGLEFINANCE(A26,""price"") - INDEX(GOOGLEFINANCE(A26,""price"",TODAY()-1095),2,2)) / INDEX(GOOGLEFINANCE(A26,""price"",TODAY()-1095),2,2))"),0.6394129979035639) -> 0.639413 | M26: =IFERROR(__xludf.DUMMYFUNCTION(" ((GOOGLEFINANCE(A26,""price"") - INDEX(GOOGLEFINANCE(A26,""price"",TODAY()-1825),2,2)) / INDEX(GOOGLEFINANCE(A26,""price"",TODAY()-1825),2,2))"),0.8680468661130702) -> 0.86804687 | N26: =IFERROR(__xludf.DUMMYFUNCTION(" ((GOOGLEFINANCE(A26,""price"") - INDEX(GOOGLEFINANCE(A26,""price"",TODAY()-3650),2,2)) / INDEX(GOOGLEFINANCE(A26,""price"",TODAY()-3650),2,2))"),2.3929752066115704) -> 2.3929752 | O26: =IFERROR(__xludf.DUMMYFUNCTION(" ((GOOGLEFINANCE(A26,""price"") - INDEX(GOOGLEFINANCE(A26,""price"",TODAY()-7300),2,2)) / INDEX(GOOGLEFINANCE(A26,""price"",TODAY()-7300),2,2))"),4.1820763647838435) -> 4.1820764
A27: XLE | B27: =IFERROR(__xludf.DUMMYFUNCTION("GOOGLEFINANCE(A27,""name"")"),"State Street Energy Select Sector SPDR ETF") -> State Street Energy Select Sector SPDR ETF | C27: =IFERROR(__xludf.DUMMYFUNCTION("GOOGLEFINANCE(A27,""price"")"),49.19) -> 49.19 | D27: =IFERROR(__xludf.DUMMYFUNCTION("GOOGLEFINANCE(A27,""changepct"")"),0.57) -> 0.57 | E27: =IFERROR(__xludf.DUMMYFUNCTION(" ((GOOGLEFINANCE(A27,""price"") - INDEX(GOOGLEFINANCE(A27,""price"",TODAY()-7),2,2)) / INDEX(GOOGLEFINANCE(A27,""price"",TODAY()-7),2,2)) "),0.03340336134453774) -> 0.033403361 | F27: =IFERROR(__xludf.DUMMYFUNCTION(" ((GOOGLEFINANCE(A27,""price"") - INDEX(GOOGLEFINANCE(A27,""price"",TODAY()-30),2,2)) / INDEX(GOOGLEFINANCE(A27,""price"",TODAY()-30),2,2)) "),0.11289592760180983) -> 0.11289593 | G27: =IFERROR(__xludf.DUMMYFUNCTION(" ((GOOGLEFINANCE(A27,""price"") - INDEX(GOOGLEFINANCE(A27,""price"",TODAY()-90),2,2)) / INDEX(GOOGLEFINANCE(A27,""price"",TODAY()-90),2,2))"),0.11440869959220655) -> 0.1144087 | H27: =IFERROR(__xludf.DUMMYFUNCTION(" ((GOOGLEFINANCE(A27,""price"") - INDEX(GOOGLEFINANCE(A27,""price"",TODAY()-182),2,2)) / INDEX(GOOGLEFINANCE(A27,""price"",TODAY()-182),2,2))"),0.11668558456299662) -> 0.11668558 | I27: =IFERROR(__xludf.DUMMYFUNCTION("(GOOGLEFINANCE(A27,""price"")-INDEX(GOOGLEFINANCE(A27,""price"",""01-01-""&YEAR(TODAY())),2,2))/INDEX(GOOGLEFINANCE(A27,""price"",""01-01-""&YEAR(TODAY())),2,2)"),0.07754654983570644) -> 0.07754655 | J27: =IFERROR(__xludf.DUMMYFUNCTION(" ((GOOGLEFINANCE(A27,""price"") - INDEX(GOOGLEFINANCE(A27,""price"",TODAY()-365),2,2)) / INDEX(GOOGLEFINANCE(A27,""price"",TODAY()-365),2,2)) "),0.07731055628558917) -> 0.077310556 | K27: =IFERROR(__xludf.DUMMYFUNCTION(" ((GOOGLEFINANCE(A27,""price"") - INDEX(GOOGLEFINANCE(A27,""price"",TODAY()-730),2,2)) / INDEX(GOOGLEFINANCE(A27,""price"",TODAY()-730),2,2))"),0.17623146819703486) -> 0.17623147 | L27: =IFERROR(__xludf.DUMMYFUNCTION(" ((GOOGLEFINANCE(A27,""price"") - INDEX(GOOGLEFINANCE(A27,""price"",TODAY()-1095),2,2)) / INDEX(GOOGLEFINANCE(A27,""price"",TODAY()-1095),2,2))"),0.08996233104365156) -> 0.089962331 | M27: =IFERROR(__xludf.DUMMYFUNCTION(" ((GOOGLEFINANCE(A27,""price"") - INDEX(GOOGLEFINANCE(A27,""price"",TODAY()-1825),2,2)) / INDEX(GOOGLEFINANCE(A27,""price"",TODAY()-1825),2,2))"),1.3626320845341018) -> 1.3626321 | N27: =IFERROR(__xludf.DUMMYFUNCTION(" ((GOOGLEFINANCE(A27,""price"") - INDEX(GOOGLEFINANCE(A27,""price"",TODAY()-3650),2,2)) / INDEX(GOOGLEFINANCE(A27,""price"",TODAY()-3650),2,2))"),0.7919854280510018) -> 0.79198543 | O27: =IFERROR(__xludf.DUMMYFUNCTION(" ((GOOGLEFINANCE(A27,""price"") - INDEX(GOOGLEFINANCE(A27,""price"",TODAY()-7300),2,2)) / INDEX(GOOGLEFINANCE(A27,""price"",TODAY()-7300),2,2))"),0.6973775017253278) -> 0.6973775
A28: XLB | B28: =IFERROR(__xludf.DUMMYFUNCTION("GOOGLEFINANCE(A28,""name"")"),"State Street Materials Select Sector SPDR ETF") -> State Street Materials Select Sector SPDR ETF | C28: =IFERROR(__xludf.DUMMYFUNCTION("GOOGLEFINANCE(A28,""price"")"),49.97) -> 49.97 | D28: =IFERROR(__xludf.DUMMYFUNCTION("GOOGLEFINANCE(A28,""changepct"")"),0.91) -> 0.91 | E28: =IFERROR(__xludf.DUMMYFUNCTION(" ((GOOGLEFINANCE(A28,""price"") - INDEX(GOOGLEFINANCE(A28,""price"",TODAY()-7),2,2)) / INDEX(GOOGLEFINANCE(A28,""price"",TODAY()-7),2,2)) "),0.03693712388462339) -> 0.036937124 | F28: =IFERROR(__xludf.DUMMYFUNCTION(" ((GOOGLEFINANCE(A28,""price"") - INDEX(GOOGLEFINANCE(A28,""price"",TODAY()-30),2,2)) / INDEX(GOOGLEFINANCE(A28,""price"",TODAY()-30),2,2)) "),0.08371286055085664) -> 0.083712861 | G28: =IFERROR(__xludf.DUMMYFUNCTION(" ((GOOGLEFINANCE(A28,""price"") - INDEX(GOOGLEFINANCE(A28,""price"",TODAY()-90),2,2)) / INDEX(GOOGLEFINANCE(A28,""price"",TODAY()-90),2,2))"),0.12317374690941778) -> 0.12317375 | H28: =IFERROR(__xludf.DUMMYFUNCTION(" ((GOOGLEFINANCE(A28,""price"") - INDEX(GOOGLEFINANCE(A28,""price"",TODAY()-182),2,2)) / INDEX(GOOGLEFINANCE(A28,""price"",TODAY()-182),2,2))"),0.09775922671353242) -> 0.097759227 | I28: =IFERROR(__xludf.DUMMYFUNCTION("(GOOGLEFINANCE(A28,""price"")-INDEX(GOOGLEFINANCE(A28,""price"",""01-01-""&YEAR(TODAY())),2,2))/INDEX(GOOGLEFINANCE(A28,""price"",""01-01-""&YEAR(TODAY())),2,2)"),0.08347788378143976) -> 0.083477884 | J28: =IFERROR(__xludf.DUMMYFUNCTION(" ((GOOGLEFINANCE(A28,""price"") - INDEX(GOOGLEFINANCE(A28,""price"",TODAY()-365),2,2)) / INDEX(GOOGLEFINANCE(A28,""price"",TODAY()-365),2,2)) "),0.12292134831460672) -> 0.12292135 | K28: =IFERROR(__xludf.DUMMYFUNCTION(" ((GOOGLEFINANCE(A28,""price"") - INDEX(GOOGLEFINANCE(A28,""price"",TODAY()-730),2,2)) / INDEX(GOOGLEFINANCE(A28,""price"",TODAY()-730),2,2))"),0.21168768186226955) -> 0.21168768 | L28: =IFERROR(__xludf.DUMMYFUNCTION(" ((GOOGLEFINANCE(A28,""price"") - INDEX(GOOGLEFINANCE(A28,""price"",TODAY()-1095),2,2)) / INDEX(GOOGLEFINANCE(A28,""price"",TODAY()-1095),2,2))"),0.20004803073967334) -> 0.20004803 | M28: =IFERROR(__xludf.DUMMYFUNCTION(" ((GOOGLEFINANCE(A28,""price"") - INDEX(GOOGLEFINANCE(A28,""price"",TODAY()-1825),2,2)) / INDEX(GOOGLEFINANCE(A28,""price"",TODAY()-1825),2,2))"),0.35090565017572306) -> 0.35090565 | N28: =IFERROR(__xludf.DUMMYFUNCTION(" ((GOOGLEFINANCE(A28,""price"") - INDEX(GOOGLEFINANCE(A28,""price"",TODAY()-3650),2,2)) / INDEX(GOOGLEFINANCE(A28,""price"",TODAY()-3650),2,2))"),1.6565656565656568) -> 1.6565657 | O28: =IFERROR(__xludf.DUMMYFUNCTION(" ((GOOGLEFINANCE(A28,""price"") - INDEX(GOOGLEFINANCE(A28,""price"",TODAY()-7300),2,2)) / INDEX(GOOGLEFINANCE(A28,""price"",TODAY()-7300),2,2))"),2.1526813880126183) -> 2.1526814
A29: XLU | B29: =IFERROR(__xludf.DUMMYFUNCTION("GOOGLEFINANCE(A29,""name"")"),"State Street Utilities Select Sector SPDR ETF") -> State Street Utilities Select Sector SPDR ETF | C29: =IFERROR(__xludf.DUMMYFUNCTION("GOOGLEFINANCE(A29,""price"")"),42.56) -> 42.56 | D29: =IFERROR(__xludf.DUMMYFUNCTION("GOOGLEFINANCE(A29,""changepct"")"),-0.35) -> -0.35 | E29: =IFERROR(__xludf.DUMMYFUNCTION(" ((GOOGLEFINANCE(A29,""price"") - INDEX(GOOGLEFINANCE(A29,""price"",TODAY()-7),2,2)) / INDEX(GOOGLEFINANCE(A29,""price"",TODAY()-7),2,2)) "),-0.009310986964618215) -> -0.009310987 | F29: =IFERROR(__xludf.DUMMYFUNCTION(" ((GOOGLEFINANCE(A29,""price"") - INDEX(GOOGLEFINANCE(A29,""price"",TODAY()-30),2,2)) / INDEX(GOOGLEFINANCE(A29,""price"",TODAY()-30),2,2)) "),-0.0051425899953248914) -> -0.00514259 | G29: =IFERROR(__xludf.DUMMYFUNCTION(" ((GOOGLEFINANCE(A29,""price"") - INDEX(GOOGLEFINANCE(A29,""price"",TODAY()-90),2,2)) / INDEX(GOOGLEFINANCE(A29,""price"",TODAY()-90),2,2))"),-0.0711479703186381) -> -0.07114797 | H29: =IFERROR(__xludf.DUMMYFUNCTION(" ((GOOGLEFINANCE(A29,""price"") - INDEX(GOOGLEFINANCE(A29,""price"",TODAY()-182),2,2)) / INDEX(GOOGLEFINANCE(A29,""price"",TODAY()-182),2,2))"),0.01793829227457546) -> 0.017938292 | I29: =IFERROR(__xludf.DUMMYFUNCTION("(GOOGLEFINANCE(A29,""price"")-INDEX(GOOGLEFINANCE(A29,""price"",""01-01-""&YEAR(TODAY())),2,2))/INDEX(GOOGLEFINANCE(A29,""price"",""01-01-""&YEAR(TODAY())),2,2)"),-0.014358499305233845) -> -0.014358499 | J29: =IFERROR(__xludf.DUMMYFUNCTION(" ((GOOGLEFINANCE(A29,""price"") - INDEX(GOOGLEFINANCE(A29,""price"",TODAY()-365),2,2)) / INDEX(GOOGLEFINANCE(A29,""price"",TODAY()-365),2,2)) "),0.07096124811273277) -> 0.070961248 | K29: =IFERROR(__xludf.DUMMYFUNCTION(" ((GOOGLEFINANCE(A29,""price"") - INDEX(GOOGLEFINANCE(A29,""price"",TODAY()-730),2,2)) / INDEX(GOOGLEFINANCE(A29,""price"",TODAY()-730),2,2))"),0.3944954128440368) -> 0.39449541 | L29: =IFERROR(__xludf.DUMMYFUNCTION(" ((GOOGLEFINANCE(A29,""price"") - INDEX(GOOGLEFINANCE(A29,""price"",TODAY()-1095),2,2)) / INDEX(GOOGLEFINANCE(A29,""price"",TODAY()-1095),2,2))"),0.23973201281677844) -> 0.23973201 | M29: =IFERROR(__xludf.DUMMYFUNCTION(" ((GOOGLEFINANCE(A29,""price"") - INDEX(GOOGLEFINANCE(A29,""price"",TODAY()-1825),2,2)) / INDEX(GOOGLEFINANCE(A29,""price"",TODAY()-1825),2,2))"),0.32792511700468036) -> 0.32792512 | N29: =IFERROR(__xludf.DUMMYFUNCTION(" ((GOOGLEFINANCE(A29,""price"") - INDEX(GOOGLEFINANCE(A29,""price"",TODAY()-3650),2,2)) / INDEX(GOOGLEFINANCE(A29,""price"",TODAY()-3650),2,2))"),0.9416058394160584) -> 0.94160584 | O29: =IFERROR(__xludf.DUMMYFUNCTION(" ((GOOGLEFINANCE(A29,""price"") - INDEX(GOOGLEFINANCE(A29,""price"",TODAY()-7300),2,2)) / INDEX(GOOGLEFINANCE(A29,""price"",TODAY()-7300),2,2))"),1.6451211932877565) -> 1.6451212
A30: XLRE | B30: =IFERROR(__xludf.DUMMYFUNCTION("GOOGLEFINANCE(A30,""name"")"),"State Street Real Estate Select Sector SPDR ETF") -> State Street Real Estate Select Sector SPDR ETF | C30: =IFERROR(__xludf.DUMMYFUNCTION("GOOGLEFINANCE(A30,""price"")"),41.25) -> 41.25 | D30: =IFERROR(__xludf.DUMMYFUNCTION("GOOGLEFINANCE(A30,""changepct"")"),0.27) -> 0.27 | E30: =IFERROR(__xludf.DUMMYFUNCTION(" ((GOOGLEFINANCE(A30,""price"") - INDEX(GOOGLEFINANCE(A30,""price"",TODAY()-7),2,2)) / INDEX(GOOGLEFINANCE(A30,""price"",TODAY()-7),2,2)) "),-0.0036231884057970672) -> -0.0036231884 | F30: =IFERROR(__xludf.DUMMYFUNCTION(" ((GOOGLEFINANCE(A30,""price"") - INDEX(GOOGLEFINANCE(A30,""price"",TODAY()-30),2,2)) / INDEX(GOOGLEFINANCE(A30,""price"",TODAY()-30),2,2)) "),0.018015794669299035) -> 0.018015795 | G30: =IFERROR(__xludf.DUMMYFUNCTION(" ((GOOGLEFINANCE(A30,""price"") - INDEX(GOOGLEFINANCE(A30,""price"",TODAY()-90),2,2)) / INDEX(GOOGLEFINANCE(A30,""price"",TODAY()-90),2,2))"),-0.034861956013102526) -> -0.034861956 | H30: =IFERROR(__xludf.DUMMYFUNCTION(" ((GOOGLEFINANCE(A30,""price"") - INDEX(GOOGLEFINANCE(A30,""price"",TODAY()-182),2,2)) / INDEX(GOOGLEFINANCE(A30,""price"",TODAY()-182),2,2))"),-0.01902497027348388) -> -0.01902497 | I30: =IFERROR(__xludf.DUMMYFUNCTION("(GOOGLEFINANCE(A30,""price"")-INDEX(GOOGLEFINANCE(A30,""price"",""01-01-""&YEAR(TODAY())),2,2))/INDEX(GOOGLEFINANCE(A30,""price"",""01-01-""&YEAR(TODAY())),2,2)"),0.021545319465081657) -> 0.021545319 | J30: =IFERROR(__xludf.DUMMYFUNCTION(" ((GOOGLEFINANCE(A30,""price"") - INDEX(GOOGLEFINANCE(A30,""price"",TODAY()-365),2,2)) / INDEX(GOOGLEFINANCE(A30,""price"",TODAY()-365),2,2)) "),-0.007220216606498127) -> -0.0072202166 | K30: =IFERROR(__xludf.DUMMYFUNCTION(" ((GOOGLEFINANCE(A30,""price"") - INDEX(GOOGLEFINANCE(A30,""price"",TODAY()-730),2,2)) / INDEX(GOOGLEFINANCE(A30,""price"",TODAY()-730),2,2))"),0.06699430936368349) -> 0.066994309 | L30: =IFERROR(__xludf.DUMMYFUNCTION(" ((GOOGLEFINANCE(A30,""price"") - INDEX(GOOGLEFINANCE(A30,""price"",TODAY()-1095),2,2)) / INDEX(GOOGLEFINANCE(A30,""price"",TODAY()-1095),2,2))"),0.04324734446130503) -> 0.043247344 | M30: =IFERROR(__xludf.DUMMYFUNCTION(" ((GOOGLEFINANCE(A30,""price"") - INDEX(GOOGLEFINANCE(A30,""price"",TODAY()-1825),2,2)) / INDEX(GOOGLEFINANCE(A30,""price"",TODAY()-1825),2,2))"),0.11036339165545092) -> 0.11036339
A31: SPY | B31: =IFERROR(__xludf.DUMMYFUNCTION("GOOGLEFINANCE(A31,""name"")"),"SPDR S&P 500 ETF Trust") -> SPDR S&P 500 ETF Trust | C31: =IFERROR(__xludf.DUMMYFUNCTION("GOOGLEFINANCE(A31,""price"")"),689.23) -> 689.23 | D31: =IFERROR(__xludf.DUMMYFUNCTION("GOOGLEFINANCE(A31,""changepct"")"),0.04) -> 0.04 | E31: =IFERROR(__xludf.DUMMYFUNCTION(" ((GOOGLEFINANCE(A31,""price"") - INDEX(GOOGLEFINANCE(A31,""price"",TODAY()-7),2,2)) / INDEX(GOOGLEFINANCE(A31,""price"",TODAY()-7),2,2)) "),0.01719354172201065) -> 0.017193542 | F31: =IFERROR(__xludf.DUMMYFUNCTION(" ((GOOGLEFINANCE(A31,""price"") - INDEX(GOOGLEFINANCE(A31,""price"",TODAY()-30),2,2)) / INDEX(GOOGLEFINANCE(A31,""price"",TODAY()-30),2,2)) "),-0.0015645144934883274) -> -0.0015645145 | G31: =IFERROR(__xludf.DUMMYFUNCTION(" ((GOOGLEFINANCE(A31,""price"") - INDEX(GOOGLEFINANCE(A31,""price"",TODAY()-90),2,2)) / INDEX(GOOGLEFINANCE(A31,""price"",TODAY()-90),2,2))"),0.005822777421049572) -> 0.0058227774 | H31: =IFERROR(__xludf.DUMMYFUNCTION(" ((GOOGLEFINANCE(A31,""price"") - INDEX(GOOGLEFINANCE(A31,""price"",TODAY()-182),2,2)) / INDEX(GOOGLEFINANCE(A31,""price"",TODAY()-182),2,2))"),0.0820956448017081) -> 0.082095645 | I31: =IFERROR(__xludf.DUMMYFUNCTION("(GOOGLEFINANCE(A31,""price"")-INDEX(GOOGLEFINANCE(A31,""price"",""01-01-""&YEAR(TODAY())),2,2))/INDEX(GOOGLEFINANCE(A31,""price"",""01-01-""&YEAR(TODAY())),2,2)"),0.008870412927968236) -> 0.0088704129 | J31: =IFERROR(__xludf.DUMMYFUNCTION(" ((GOOGLEFINANCE(A31,""price"") - INDEX(GOOGLEFINANCE(A31,""price"",TODAY()-365),2,2)) / INDEX(GOOGLEFINANCE(A31,""price"",TODAY()-365),2,2)) "),0.13365791075217526) -> 0.13365791 | K31: =IFERROR(__xludf.DUMMYFUNCTION(" ((GOOGLEFINANCE(A31,""price"") - INDEX(GOOGLEFINANCE(A31,""price"",TODAY()-730),2,2)) / INDEX(GOOGLEFINANCE(A31,""price"",TODAY()-730),2,2))"),0.41226973751613644) -> 0.41226974 | L31: =IFERROR(__xludf.DUMMYFUNCTION(" ((GOOGLEFINANCE(A31,""price"") - INDEX(GOOGLEFINANCE(A31,""price"",TODAY()-1095),2,2)) / INDEX(GOOGLEFINANCE(A31,""price"",TODAY()-1095),2,2))"),0.7215686274509804) -> 0.72156863 | M31: =IFERROR(__xludf.DUMMYFUNCTION(" ((GOOGLEFINANCE(A31,""price"") - INDEX(GOOGLEFINANCE(A31,""price"",TODAY()-1825),2,2)) / INDEX(GOOGLEFINANCE(A31,""price"",TODAY()-1825),2,2))"),0.7930487265537606) -> 0.79304873 | N31: =IFERROR(__xludf.DUMMYFUNCTION(" ((GOOGLEFINANCE(A31,""price"") - INDEX(GOOGLEFINANCE(A31,""price"",TODAY()-3650),2,2)) / INDEX(GOOGLEFINANCE(A31,""price"",TODAY()-3650),2,2))"),2.663583692127784) -> 2.6635837 | O31: =IFERROR(__xludf.DUMMYFUNCTION(" ((GOOGLEFINANCE(A31,""price"") - INDEX(GOOGLEFINANCE(A31,""price"",TODAY()-7300),2,2)) / INDEX(GOOGLEFINANCE(A31,""price"",TODAY()-7300),2,2))"),4.366163189037683) -> 4.3661632
A51: Utilizzare FundFlow e Aum come indicatore di interesse/disinteresse sui settori.
A53: | CATEGORIA | CONDIZIONE / FILTRO | SIGNIFICATO / INTERPRETAZIONE | COMMENTO OPERATIVO |
A55: | ETF selezionabili | AUM > $5 miliardi | Solo ETF liquidi e seguiti dagli istituzionali | SPY, QQQ, XLK, XLV, ecc. |
A56: | Volume medio | > 1M giornaliero | Evita rumore da ETF illiquidi
A57: | Flusso Anomalo | Fund Flow > ±2% dell’AUM in 1 giorno | Segnale forte di ingresso/uscita capitale | Va tracciato e confermato |
A58: | Divergenza AUM | AUM sale/scende ma prezzo va nella direzione opposta | Possibile segnale contrarian o accumulo/distribuzione nascosta | Osservare evoluzione nei giorni successivi |
A59: | Combinazione 1 | Prezzo in calo + Afflussi forti | Accumulo istituzionale, contrarian bullish | Potenziale bottom, osservare follow-through |
A60: | Combinazione 2 | Prezzo in rialzo + Deflussi forti | Distribuzione, riduzione esposizione | Potenziale esaurimento rally |
A61: | Combinazione 3 | AUM in calo costante + prezzo stabile | Perdita d’interesse, rotazione lenta | Bearish debole, trend in deterioramento |
A62: | Combinazione 4 | AUM picco dopo rally forte | Capitale "late" in entrata | Segnale contrarian, attenzione a top di breve |
A63: | Combinazione 5 | Flussi elevati senza notizie macro evidenti | Mossa istituzionale o anticipazione informata | Va monitorata con molta attenzione |
A67: Rotazionali su Momentum | C67: : si compra il migliore sul momentum e si vende il peggiore in PTF in base alla tabella | H67: al 22.01 | I67: changepct | J67: Classifica
...

Sheet Fattori
D1: CAMBIO | E1: =IFERROR(__xludf.DUMMYFUNCTION("GOOGLEFINANCE(""CURRENCY:GBPEUR"")"),1.1538) -> 1.1538
A14: ticker | B14: Fattori | C14: Prezzo corrente | D14: Var. % giornaliera | E14: Var. % settimanale | F14: Var. % mensile | G14: Var. % trimestrale | H14: Var.%semestrale | I14: Variaz .% YTD | J14: Var. % annuale | K14: Var. % 2 anni | L14: Var. % 3 anni | M14: Var. % 5 anni | N14: Var.% 10anni
A15: LON:MVOL | B15: Minimum Volat. | C15: =IFERROR(__xludf.DUMMYFUNCTION("GOOGLEFINANCE(A15,""PRICE"")"),73.38) -> 73.38 | D15: =IFERROR(__xludf.DUMMYFUNCTION("GOOGLEFINANCE(A15,""changepct"")/100"),0.0) -> 0 | E15: =IFERROR(__xludf.DUMMYFUNCTION(" ((GOOGLEFINANCE(A15,""price"") - INDEX(GOOGLEFINANCE(A15,""price"",TODAY()-7),2,2)) / INDEX(GOOGLEFINANCE(A15,""price"",TODAY()-7),2,2)) "),0.0025959830577947495) -> 0.0025959831 | F15: =IFERROR(__xludf.DUMMYFUNCTION(" ((GOOGLEFINANCE(A15,""price"") - INDEX(GOOGLEFINANCE(A15,""price"",TODAY()-30),2,2)) / INDEX(GOOGLEFINANCE(A15,""price"",TODAY()-30),2,2)) "),-0.003801248981808324) -> -0.003801249 | G15: =IFERROR(__xludf.DUMMYFUNCTION(" ((GOOGLEFINANCE(A15,""price"") - INDEX(GOOGLEFINANCE(A15,""price"",TODAY()-90),2,2)) / INDEX(GOOGLEFINANCE(A15,""price"",TODAY()-90),2,2))"),-0.0012249897917517819) -> -0.0012249898 | H15: =IFERROR(__xludf.DUMMYFUNCTION(" ((GOOGLEFINANCE(A15,""price"") - INDEX(GOOGLEFINANCE(A15,""price"",TODAY()-182),2,2)) / INDEX(GOOGLEFINANCE(A15,""price"",TODAY()-182),2,2))"),0.012696660226331794) -> 0.01269666 | I15: =IFERROR(__xludf.DUMMYFUNCTION("(GOOGLEFINANCE(A15,""price"")-INDEX(GOOGLEFINANCE(A15,""price"",""01-01-""&YEAR(TODAY())),2,2))/INDEX(GOOGLEFINANCE(A15,""price"",""01-01-""&YEAR(TODAY())),2,2)"),0.005205479452054732) -> 0.0052054795 | J15: =IFERROR(__xludf.DUMMYFUNCTION(" ((GOOGLEFINANCE(A15,""price"") - INDEX(GOOGLEFINANCE(A15,""price"",TODAY()-365),2,2)) / INDEX(GOOGLEFINANCE(A15,""price"",TODAY()-365),2,2)) "),0.08969408969408957) -> 0.08969409 | K15: =IFERROR(__xludf.DUMMYFUNCTION(" ((GOOGLEFINANCE(A15,""price"") - INDEX(GOOGLEFINANCE(A15,""price"",TODAY()-730),2,2)) / INDEX(GOOGLEFINANCE(A15,""price"",TODAY()-730),2,2))"),0.21009234828496035) -> 0.21009235 | L15: =IFERROR(__xludf.DUMMYFUNCTION(" ((GOOGLEFINANCE(A15,""price"") - INDEX(GOOGLEFINANCE(A15,""price"",TODAY()-1095),2,2)) / INDEX(GOOGLEFINANCE(A15,""price"",TODAY()-1095),2,2))"),0.30708941930887057) -> 0.30708942 | M15: =IFERROR(__xludf.DUMMYFUNCTION(" ((GOOGLEFINANCE(A15,""price"") - INDEX(GOOGLEFINANCE(A15,""price"",TODAY()-1825),2,2)) / INDEX(GOOGLEFINANCE(A15,""price"",TODAY()-1825),2,2))"),0.3573806881243062) -> 0.35738069 | N15: =IFERROR(__xludf.DUMMYFUNCTION(" ((GOOGLEFINANCE(A15,""price"") - INDEX(GOOGLEFINANCE(A15,""price"",TODAY()-3650),2,2)) / INDEX(GOOGLEFINANCE(A15,""price"",TODAY()-3650),2,2))"),1.1937219730941702) -> 1.193722
A16: LON:IWQU | B16: World Quality | C16: =IFERROR(__xludf.DUMMYFUNCTION("GOOGLEFINANCE(A16,""price"")"),81.96) -> 81.96 | D16: =IFERROR(__xludf.DUMMYFUNCTION("GOOGLEFINANCE(A16,""changepct"")/100"),0.0019) -> 0.0019 | E16: =IFERROR(__xludf.DUMMYFUNCTION(" ((GOOGLEFINANCE(A16,""price"") - INDEX(GOOGLEFINANCE(A16,""price"",TODAY()-7),2,2)) / INDEX(GOOGLEFINANCE(A16,""price"",TODAY()-7),2,2)) "),0.009981515711644955) -> 0.0099815157 | F16: =IFERROR(__xludf.DUMMYFUNCTION(" ((GOOGLEFINANCE(A16,""price"") - INDEX(GOOGLEFINANCE(A16,""price"",TODAY()-30),2,2)) / INDEX(GOOGLEFINANCE(A16,""price"",TODAY()-30),2,2)) "),0.022072577628133135) -> 0.022072578 | G16: =IFERROR(__xludf.DUMMYFUNCTION(" ((GOOGLEFINANCE(A16,""price"") - INDEX(GOOGLEFINANCE(A16,""price"",TODAY()-90),2,2)) / INDEX(GOOGLEFINANCE(A16,""price"",TODAY()-90),2,2))"),0.03917839482693025) -> 0.039178395 | H16: =IFERROR(__xludf.DUMMYFUNCTION(" ((GOOGLEFINANCE(A16,""price"") - INDEX(GOOGLEFINANCE(A16,""price"",TODAY()-182),2,2)) / INDEX(GOOGLEFINANCE(A16,""price"",TODAY()-182),2,2))"),0.10176098938029296) -> 0.10176099 | I16: =IFERROR(__xludf.DUMMYFUNCTION("(GOOGLEFINANCE(A16,""price"")-INDEX(GOOGLEFINANCE(A16,""price"",""01-01-""&YEAR(TODAY())),2,2))/INDEX(GOOGLEFINANCE(A16,""price"",""01-01-""&YEAR(TODAY())),2,2)"),0.025012506253126565) -> 0.025012506 | J16: =IFERROR(__xludf.DUMMYFUNCTION(" ((GOOGLEFINANCE(A16,""price"") - INDEX(GOOGLEFINANCE(A16,""price"",TODAY()-365),2,2)) / INDEX(GOOGLEFINANCE(A16,""price"",TODAY()-365),2,2)) "),0.14485263304930843) -> 0.14485263 | K16: =IFERROR(__xludf.DUMMYFUNCTION(" ((GOOGLEFINANCE(A16,""price"") - INDEX(GOOGLEFINANCE(A16,""price"",TODAY()-730),2,2)) / INDEX(GOOGLEFINANCE(A16,""price"",TODAY()-730),2,2))"),0.35672901837444126) -> 0.35672902 | L16: =IFERROR(__xludf.DUMMYFUNCTION(" ((GOOGLEFINANCE(A16,""price"") - INDEX(GOOGLEFINANCE(A16,""price"",TODAY()-1095),2,2)) / INDEX(GOOGLEFINANCE(A16,""price"",TODAY()-1095),2,2))"),0.6618004866180047) -> 0.66180049 | M16: =IFERROR(__xludf.DUMMYFUNCTION(" ((GOOGLEFINANCE(A16,""price"") - INDEX(GOOGLEFINANCE(A16,""price"",TODAY()-1825),2,2)) / INDEX(GOOGLEFINANCE(A16,""price"",TODAY()-1825),2,2))"),0.7135688898181057) -> 0.71356889 | N16: =IFERROR(__xludf.DUMMYFUNCTION(" ((GOOGLEFINANCE(A16,""price"") - INDEX(GOOGLEFINANCE(A16,""price"",TODAY()-3650),2,2)) / INDEX(GOOGLEFINANCE(A16,""price"",TODAY()-3650),2,2))"),"#N/A") -> #N/A
A17: LON:IWMO | B17: World Momentum | C17: =IFERROR(__xludf.DUMMYFUNCTION("GOOGLEFINANCE(A17,""price"")"),100.06) -> 100.06 | D17: =IFERROR(__xludf.DUMMYFUNCTION("GOOGLEFINANCE(A17,""changepct"")/100"),-0.0014000000000000002) -> -0.0014 | E17: =IFERROR(__xludf.DUMMYFUNCTION(" ((GOOGLEFINANCE(A17,""price"") - INDEX(GOOGLEFINANCE(A17,""price"",TODAY()-7),2,2)) / INDEX(GOOGLEFINANCE(A17,""price"",TODAY()-7),2,2)) "),-0.0028898854010960843) -> -0.0028898854 | F17: =IFERROR(__xludf.DUMMYFUNCTION(" ((GOOGLEFINANCE(A17,""price"") - INDEX(GOOGLEFINANCE(A17,""price"",TODAY()-30),2,2)) / INDEX(GOOGLEFINANCE(A17,""price"",TODAY()-30),2,2)) "),0.022794643769804803) -> 0.022794644 | G17: =IFERROR(__xludf.DUMMYFUNCTION(" ((GOOGLEFINANCE(A17,""price"") - INDEX(GOOGLEFINANCE(A17,""price"",TODAY()-90),2,2)) / INDEX(GOOGLEFINANCE(A17,""price"",TODAY()-90),2,2))"),0.03926049023680932) -> 0.03926049 | H17: =IFERROR(__xludf.DUMMYFUNCTION(" ((GOOGLEFINANCE(A17,""price"") - INDEX(GOOGLEFINANCE(A17,""price"",TODAY()-182),2,2)) / INDEX(GOOGLEFINANCE(A17,""price"",TODAY()-182),2,2))"),0.10600198960981545) -> 0.10600199 | I17: =IFERROR(__xludf.DUMMYFUNCTION("(GOOGLEFINANCE(A17,""price"")-INDEX(GOOGLEFINANCE(A17,""price"",""01-01-""&YEAR(TODAY())),2,2))/INDEX(GOOGLEFINANCE(A17,""price"",""01-01-""&YEAR(TODAY())),2,2)"),0.020812079167516897) -> 0.020812079 | J17: =IFERROR(__xludf.DUMMYFUNCTION(" ((GOOGLEFINANCE(A17,""price"") - INDEX(GOOGLEFINANCE(A17,""price"",TODAY()-365),2,2)) / INDEX(GOOGLEFINANCE(A17,""price"",TODAY()-365),2,2)) "),0.1831618777344213) -> 0.18316188 | K17: =IFERROR(__xludf.DUMMYFUNCTION(" ((GOOGLEFINANCE(A17,""price"") - INDEX(GOOGLEFINANCE(A17,""price"",TODAY()-730),2,2)) / INDEX(GOOGLEFINANCE(A17,""price"",TODAY()-730),2,2))"),0.5304374426430102) -> 0.53043744 | L17: =IFERROR(__xludf.DUMMYFUNCTION(" ((GOOGLEFINANCE(A17,""price"") - INDEX(GOOGLEFINANCE(A17,""price"",TODAY()-1095),2,2)) / INDEX(GOOGLEFINANCE(A17,""price"",TODAY()-1095),2,2))"),0.7986697824914614) -> 0.79866978 | M17: =IFERROR(__xludf.DUMMYFUNCTION(" ((GOOGLEFINANCE(A17,""price"") - INDEX(GOOGLEFINANCE(A17,""price"",TODAY()-1825),2,2)) / INDEX(GOOGLEFINANCE(A17,""price"",TODAY()-1825),2,2))"),0.6240869988638209) -> 0.624087 | N17: =IFERROR(__xludf.DUMMYFUNCTION(" ((GOOGLEFINANCE(A17,""price"") - INDEX(GOOGLEFINANCE(A17,""price"",TODAY()-3650),2,2)) / INDEX(GOOGLEFINANCE(A17,""price"",TODAY()-3650),2,2))"),2.9177760375880974) -> 2.917776
A18: LON:IWVL | B18: World Value | C18: =IFERROR(__xludf.DUMMYFUNCTION("GOOGLEFINANCE(A18,""price"")"),62.72) -> 62.72 | D18: =IFERROR(__xludf.DUMMYFUNCTION("GOOGLEFINANCE(A18,""changepct"")/100"),-0.0084) -> -0.0084 | E18: =IFERROR(__xludf.DUMMYFUNCTION(" ((GOOGLEFINANCE(A18,""price"") - INDEX(GOOGLEFINANCE(A18,""price"",TODAY()-7),2,2)) / INDEX(GOOGLEFINANCE(A18,""price"",TODAY()-7),2,2)) "),0.013247172859450733) -> 0.013247173 | F18: =IFERROR(__xludf.DUMMYFUNCTION(" ((GOOGLEFINANCE(A18,""price"") - INDEX(GOOGLEFINANCE(A18,""price"",TODAY()-30),2,2)) / INDEX(GOOGLEFINANCE(A18,""price"",TODAY()-30),2,2)) "),0.043767681810617326) -> 0.043767682 | G18: =IFERROR(__xludf.DUMMYFUNCTION(" ((GOOGLEFINANCE(A18,""price"") - INDEX(GOOGLEFINANCE(A18,""price"",TODAY()-90),2,2)) / INDEX(GOOGLEFINANCE(A18,""price"",TODAY()-90),2,2))"),0.1108749557208643) -> 0.11087496 | H18: =IFERROR(__xludf.DUMMYFUNCTION(" ((GOOGLEFINANCE(A18,""price"") - INDEX(GOOGLEFINANCE(A18,""price"",TODAY()-182),2,2)) / INDEX(GOOGLEFINANCE(A18,""price"",TODAY()-182),2,2))"),0.24001581652827206) -> 0.24001582 | I18: =IFERROR(__xludf.DUMMYFUNCTION("(GOOGLEFINANCE(A18,""price"")-INDEX(GOOGLEFINANCE(A18,""price"",""01-01-""&YEAR(TODAY())),2,2))/INDEX(GOOGLEFINANCE(A18,""price"",""01-01-""&YEAR(TODAY())),2,2)"),0.03378935223339372) -> 0.033789352 | J18: =IFERROR(__xludf.DUMMYFUNCTION(" ((GOOGLEFINANCE(A18,""price"") - INDEX(GOOGLEFINANCE(A18,""price"",TODAY()-365),2,2)) / INDEX(GOOGLEFINANCE(A18,""price"",TODAY()-365),2,2)) "),0.40912154572006293) -> 0.40912155 | K18: =IFERROR(__xludf.DUMMYFUNCTION(" ((GOOGLEFINANCE(A18,""price"") - INDEX(GOOGLEFINANCE(A18,""price"",TODAY()-730),2,2)) / INDEX(GOOGLEFINANCE(A18,""price"",TODAY()-730),2,2))"),0.5410319410319409) -> 0.54103194 | L18: =IFERROR(__xludf.DUMMYFUNCTION(" ((GOOGLEFINANCE(A18,""price"") - INDEX(GOOGLEFINANCE(A18,""price"",TODAY()-1095),2,2)) / INDEX(GOOGLEFINANCE(A18,""price"",TODAY()-1095),2,2))"),0.7340337296101741) -> 0.73403373 | M18: =IFERROR(__xludf.DUMMYFUNCTION(" ((GOOGLEFINANCE(A18,""price"") - INDEX(GOOGLEFINANCE(A18,""price"",TODAY()-1825),2,2)) / INDEX(GOOGLEFINANCE(A18,""price"",TODAY()-1825),2,2))"),0.9198041016222833) -> 0.9198041 | N18: =IFERROR(__xludf.DUMMYFUNCTION(" ((GOOGLEFINANCE(A18,""price"") - INDEX(GOOGLEFINANCE(A18,""price"",TODAY()-3650),2,2)) / INDEX(GOOGLEFINANCE(A18,""price"",TODAY()-3650),2,2))"),"#N/A") -> #N/A
